2022-08-17T08:46:26.922,ERROR,MainThread,140153286625088,cc_db.py:get_order_json,237,HTTPSConnectionPool(host='wcapi.covidclinic.org' port=443): Read timed out. (read timeout=5)\nTraceback (most recent call last):\n  File "/usr/lib/python3/dist-packages/urllib3/contrib/pyopenssl.py", line 485, in wrap_socket\n    cnx.do_handshake()\n  File "/usr/lib/python3/dist-packages/OpenSSL/SSL.py", line 1915, in do_handshake\n    self._raise_ssl_error(self._ssl, result)\n  File "/usr/lib/python3/dist-packages/OpenSSL/SSL.py", line 1622, in _raise_ssl_error\n    raise WantReadError()\nOpenSSL.SSL.WantReadError\n\nDuring handling of the above exception, another exception occurred:\n\nTraceback (most recent call last):\n  File "/usr/lib/python3/dist-packages/urllib3/connectionpool.py", line 376, in _make_request\n    self._validate_conn(conn)\n  File "/usr/lib/python3/dist-packages/urllib3/connectionpool.py", line 996, in _validate_conn\n    conn.connect()\n  File "/usr/lib/python3/dist-packages/urllib3/connection.py", line 366, in connect\n    self.sock = ssl_wrap_socket(\n  File "/usr/lib/python3/dist-packages/urllib3/util/ssl_.py", line 370, in ssl_wrap_socket\n    return context.wrap_socket(sock, server_hostname=server_hostname)\n  File "/usr/lib/python3/dist-packages/urllib3/contrib/pyopenssl.py", line 488, in wrap_socket\n    raise timeout("select timed out")\nsocket.timeout: select timed out\n\nDuring handling of the above exception, another exception occurred:\n\nTraceback (most recent call last):\n  File "/usr/lib/python3/dist-packages/requests/adapters.py", line 439, in send\n    resp = conn.urlopen(\n  File "/usr/lib/python3/dist-packages/urllib3/connectionpool.py", line 719, in urlopen\n    retries = retries.increment(\n  File "/usr/lib/python3/dist-packages/urllib3/util/retry.py", line 400, in increment\n    raise six.reraise(type(error), error, _stacktrace)\n  File "/usr/lib/python3/dist-packages/six.py", line 703, in reraise\n    raise value\n  File "/usr/lib/python3/dist-packages/urllib3/connectionpool.py", line 665, in urlopen\n    httplib_response = self._make_request(\n  File "/usr/lib/python3/dist-packages/urllib3/connectionpool.py", line 379, in _make_request\n    self._raise_timeout(err=e, url=url, timeout_value=conn.timeout)\n  File "/usr/lib/python3/dist-packages/urllib3/connectionpool.py", line 330, in _raise_timeout\n    raise ReadTimeoutError(\nurllib3.exceptions.ReadTimeoutError: HTTPSConnectionPool(host='wcapi.covidclinic.org', port=443): Read timed out. (read timeout=5)\n\nDuring handling of the above exception, another exception occurred:\n\nTraceback (most recent call last):\n  File "/mnt/c/Users/malonso/Documents/auxiliary_api/Caladrius/cc_archive/cc_db.py", line 193, in get_order_json\n    order_response = wc_api[stage][site_code].get(f"orders/{order_number}")\n  File "/home/malonso/.local/lib/python3.8/site-packages/woocommerce/api.py", line 106, in get\n    return self.__request("GET", endpoint, None, **kwargs)\n  File "/home/malonso/.local/lib/python3.8/site-packages/woocommerce/api.py", line 92, in __request\n    return request(\n  File "/usr/lib/python3/dist-packages/requests/api.py", line 60, in request\n    return session.request(method=method, url=url, **kwargs)\n  File "/usr/lib/python3/dist-packages/requests/sessions.py", line 533, in request\n    resp = self.send(prep, **send_kwargs)\n  File "/usr/lib/python3/dist-packages/requests/sessions.py", line 646, in send\n    r = adapter.send(request, **kwargs)\n  File "/usr/lib/python3/dist-packages/requests/adapters.py", line 529, in send\n    raise ReadTimeout(e, request=request)\nrequests.exceptions.ReadTimeout: HTTPSConnectionPool(host='wcapi.covidclinic.org', port=443): Read timed out. (read timeout=5)
2022-08-17T08:46:27.219,ERROR,MainThread,140153286625088,cc_db.py:get_cc_order,290,No order document found for mrn=[00-775325]
2022-08-18T17:12:29.892,ERROR,MainThread,139731696682816,cc_db.py:get_order_json,237,HTTPSConnectionPool(host='wcapi.covidclinic.org' port=443): Read timed out. (read timeout=5)\nTraceback (most recent call last):\n  File "/usr/lib/python3/dist-packages/urllib3/contrib/pyopenssl.py", line 485, in wrap_socket\n    cnx.do_handshake()\n  File "/usr/lib/python3/dist-packages/OpenSSL/SSL.py", line 1915, in do_handshake\n    self._raise_ssl_error(self._ssl, result)\n  File "/usr/lib/python3/dist-packages/OpenSSL/SSL.py", line 1622, in _raise_ssl_error\n    raise WantReadError()\nOpenSSL.SSL.WantReadError\n\nDuring handling of the above exception, another exception occurred:\n\nTraceback (most recent call last):\n  File "/usr/lib/python3/dist-packages/urllib3/connectionpool.py", line 376, in _make_request\n    self._validate_conn(conn)\n  File "/usr/lib/python3/dist-packages/urllib3/connectionpool.py", line 996, in _validate_conn\n    conn.connect()\n  File "/usr/lib/python3/dist-packages/urllib3/connection.py", line 366, in connect\n    self.sock = ssl_wrap_socket(\n  File "/usr/lib/python3/dist-packages/urllib3/util/ssl_.py", line 370, in ssl_wrap_socket\n    return context.wrap_socket(sock, server_hostname=server_hostname)\n  File "/usr/lib/python3/dist-packages/urllib3/contrib/pyopenssl.py", line 488, in wrap_socket\n    raise timeout("select timed out")\nsocket.timeout: select timed out\n\nDuring handling of the above exception, another exception occurred:\n\nTraceback (most recent call last):\n  File "/usr/lib/python3/dist-packages/requests/adapters.py", line 439, in send\n    resp = conn.urlopen(\n  File "/usr/lib/python3/dist-packages/urllib3/connectionpool.py", line 719, in urlopen\n    retries = retries.increment(\n  File "/usr/lib/python3/dist-packages/urllib3/util/retry.py", line 400, in increment\n    raise six.reraise(type(error), error, _stacktrace)\n  File "/usr/lib/python3/dist-packages/six.py", line 703, in reraise\n    raise value\n  File "/usr/lib/python3/dist-packages/urllib3/connectionpool.py", line 665, in urlopen\n    httplib_response = self._make_request(\n  File "/usr/lib/python3/dist-packages/urllib3/connectionpool.py", line 379, in _make_request\n    self._raise_timeout(err=e, url=url, timeout_value=conn.timeout)\n  File "/usr/lib/python3/dist-packages/urllib3/connectionpool.py", line 330, in _raise_timeout\n    raise ReadTimeoutError(\nurllib3.exceptions.ReadTimeoutError: HTTPSConnectionPool(host='wcapi.covidclinic.org', port=443): Read timed out. (read timeout=5)\n\nDuring handling of the above exception, another exception occurred:\n\nTraceback (most recent call last):\n  File "/mnt/c/Users/malonso/Documents/auxiliary_api/Caladrius/cc_archive/cc_db.py", line 193, in get_order_json\n    order_response = wc_api[stage][site_code].get(f"orders/{order_number}")\n  File "/home/malonso/.local/lib/python3.8/site-packages/woocommerce/api.py", line 106, in get\n    return self.__request("GET", endpoint, None, **kwargs)\n  File "/home/malonso/.local/lib/python3.8/site-packages/woocommerce/api.py", line 92, in __request\n    return request(\n  File "/usr/lib/python3/dist-packages/requests/api.py", line 60, in request\n    return session.request(method=method, url=url, **kwargs)\n  File "/usr/lib/python3/dist-packages/requests/sessions.py", line 533, in request\n    resp = self.send(prep, **send_kwargs)\n  File "/usr/lib/python3/dist-packages/requests/sessions.py", line 646, in send\n    r = adapter.send(request, **kwargs)\n  File "/usr/lib/python3/dist-packages/requests/adapters.py", line 529, in send\n    raise ReadTimeout(e, request=request)\nrequests.exceptions.ReadTimeout: HTTPSConnectionPool(host='wcapi.covidclinic.org', port=443): Read timed out. (read timeout=5)
2022-08-18T17:12:30.002,ERROR,MainThread,139731696682816,cc_db.py:get_cc_order,290,No order document found for mrn=[00-3772075]
2022-08-22T12:59:16.786,ERROR,MainThread,140720260122432,cc_db.py:get_order_json,237,HTTPSConnectionPool(host='wcapi.covidclinic.org' port=443): Read timed out. (read timeout=5)\nTraceback (most recent call last):\n  File "/usr/lib/python3/dist-packages/urllib3/contrib/pyopenssl.py", line 485, in wrap_socket\n    cnx.do_handshake()\n  File "/usr/lib/python3/dist-packages/OpenSSL/SSL.py", line 1915, in do_handshake\n    self._raise_ssl_error(self._ssl, result)\n  File "/usr/lib/python3/dist-packages/OpenSSL/SSL.py", line 1622, in _raise_ssl_error\n    raise WantReadError()\nOpenSSL.SSL.WantReadError\n\nDuring handling of the above exception, another exception occurred:\n\nTraceback (most recent call last):\n  File "/usr/lib/python3/dist-packages/urllib3/connectionpool.py", line 376, in _make_request\n    self._validate_conn(conn)\n  File "/usr/lib/python3/dist-packages/urllib3/connectionpool.py", line 996, in _validate_conn\n    conn.connect()\n  File "/usr/lib/python3/dist-packages/urllib3/connection.py", line 366, in connect\n    self.sock = ssl_wrap_socket(\n  File "/usr/lib/python3/dist-packages/urllib3/util/ssl_.py", line 370, in ssl_wrap_socket\n    return context.wrap_socket(sock, server_hostname=server_hostname)\n  File "/usr/lib/python3/dist-packages/urllib3/contrib/pyopenssl.py", line 488, in wrap_socket\n    raise timeout("select timed out")\nsocket.timeout: select timed out\n\nDuring handling of the above exception, another exception occurred:\n\nTraceback (most recent call last):\n  File "/usr/lib/python3/dist-packages/requests/adapters.py", line 439, in send\n    resp = conn.urlopen(\n  File "/usr/lib/python3/dist-packages/urllib3/connectionpool.py", line 719, in urlopen\n    retries = retries.increment(\n  File "/usr/lib/python3/dist-packages/urllib3/util/retry.py", line 400, in increment\n    raise six.reraise(type(error), error, _stacktrace)\n  File "/usr/lib/python3/dist-packages/six.py", line 703, in reraise\n    raise value\n  File "/usr/lib/python3/dist-packages/urllib3/connectionpool.py", line 665, in urlopen\n    httplib_response = self._make_request(\n  File "/usr/lib/python3/dist-packages/urllib3/connectionpool.py", line 379, in _make_request\n    self._raise_timeout(err=e, url=url, timeout_value=conn.timeout)\n  File "/usr/lib/python3/dist-packages/urllib3/connectionpool.py", line 330, in _raise_timeout\n    raise ReadTimeoutError(\nurllib3.exceptions.ReadTimeoutError: HTTPSConnectionPool(host='wcapi.covidclinic.org', port=443): Read timed out. (read timeout=5)\n\nDuring handling of the above exception, another exception occurred:\n\nTraceback (most recent call last):\n  File "/mnt/c/Users/malonso/Documents/auxiliary_api/Caladrius/cc_archive/cc_db.py", line 193, in get_order_json\n    order_response = wc_api[stage][site_code].get(f"orders/{order_number}")\n  File "/home/malonso/.local/lib/python3.8/site-packages/woocommerce/api.py", line 106, in get\n    return self.__request("GET", endpoint, None, **kwargs)\n  File "/home/malonso/.local/lib/python3.8/site-packages/woocommerce/api.py", line 92, in __request\n    return request(\n  File "/usr/lib/python3/dist-packages/requests/api.py", line 60, in request\n    return session.request(method=method, url=url, **kwargs)\n  File "/usr/lib/python3/dist-packages/requests/sessions.py", line 533, in request\n    resp = self.send(prep, **send_kwargs)\n  File "/usr/lib/python3/dist-packages/requests/sessions.py", line 646, in send\n    r = adapter.send(request, **kwargs)\n  File "/usr/lib/python3/dist-packages/requests/adapters.py", line 529, in send\n    raise ReadTimeout(e, request=request)\nrequests.exceptions.ReadTimeout: HTTPSConnectionPool(host='wcapi.covidclinic.org', port=443): Read timed out. (read timeout=5)
2022-08-22T12:59:16.876,ERROR,MainThread,140720260122432,cc_db.py:get_cc_order,290,No order document found for mrn=[00-854791]
2022-08-22T14:14:27.971,ERROR,MainThread,140334522763072,cc_db.py:get_order_json,237,HTTPSConnectionPool(host='wcapi.covidclinic.org' port=443): Read timed out. (read timeout=5)\nTraceback (most recent call last):\n  File "/usr/lib/python3/dist-packages/urllib3/contrib/pyopenssl.py", line 485, in wrap_socket\n    cnx.do_handshake()\n  File "/usr/lib/python3/dist-packages/OpenSSL/SSL.py", line 1915, in do_handshake\n    self._raise_ssl_error(self._ssl, result)\n  File "/usr/lib/python3/dist-packages/OpenSSL/SSL.py", line 1622, in _raise_ssl_error\n    raise WantReadError()\nOpenSSL.SSL.WantReadError\n\nDuring handling of the above exception, another exception occurred:\n\nTraceback (most recent call last):\n  File "/usr/lib/python3/dist-packages/urllib3/connectionpool.py", line 376, in _make_request\n    self._validate_conn(conn)\n  File "/usr/lib/python3/dist-packages/urllib3/connectionpool.py", line 996, in _validate_conn\n    conn.connect()\n  File "/usr/lib/python3/dist-packages/urllib3/connection.py", line 366, in connect\n    self.sock = ssl_wrap_socket(\n  File "/usr/lib/python3/dist-packages/urllib3/util/ssl_.py", line 370, in ssl_wrap_socket\n    return context.wrap_socket(sock, server_hostname=server_hostname)\n  File "/usr/lib/python3/dist-packages/urllib3/contrib/pyopenssl.py", line 488, in wrap_socket\n    raise timeout("select timed out")\nsocket.timeout: select timed out\n\nDuring handling of the above exception, another exception occurred:\n\nTraceback (most recent call last):\n  File "/usr/lib/python3/dist-packages/requests/adapters.py", line 439, in send\n    resp = conn.urlopen(\n  File "/usr/lib/python3/dist-packages/urllib3/connectionpool.py", line 719, in urlopen\n    retries = retries.increment(\n  File "/usr/lib/python3/dist-packages/urllib3/util/retry.py", line 400, in increment\n    raise six.reraise(type(error), error, _stacktrace)\n  File "/usr/lib/python3/dist-packages/six.py", line 703, in reraise\n    raise value\n  File "/usr/lib/python3/dist-packages/urllib3/connectionpool.py", line 665, in urlopen\n    httplib_response = self._make_request(\n  File "/usr/lib/python3/dist-packages/urllib3/connectionpool.py", line 379, in _make_request\n    self._raise_timeout(err=e, url=url, timeout_value=conn.timeout)\n  File "/usr/lib/python3/dist-packages/urllib3/connectionpool.py", line 330, in _raise_timeout\n    raise ReadTimeoutError(\nurllib3.exceptions.ReadTimeoutError: HTTPSConnectionPool(host='wcapi.covidclinic.org', port=443): Read timed out. (read timeout=5)\n\nDuring handling of the above exception, another exception occurred:\n\nTraceback (most recent call last):\n  File "/mnt/c/Users/malonso/Documents/auxiliary_api/Caladrius/cc_archive/cc_db.py", line 193, in get_order_json\n    order_response = wc_api[stage][site_code].get(f"orders/{order_number}")\n  File "/home/malonso/.local/lib/python3.8/site-packages/woocommerce/api.py", line 106, in get\n    return self.__request("GET", endpoint, None, **kwargs)\n  File "/home/malonso/.local/lib/python3.8/site-packages/woocommerce/api.py", line 92, in __request\n    return request(\n  File "/usr/lib/python3/dist-packages/requests/api.py", line 60, in request\n    return session.request(method=method, url=url, **kwargs)\n  File "/usr/lib/python3/dist-packages/requests/sessions.py", line 533, in request\n    resp = self.send(prep, **send_kwargs)\n  File "/usr/lib/python3/dist-packages/requests/sessions.py", line 646, in send\n    r = adapter.send(request, **kwargs)\n  File "/usr/lib/python3/dist-packages/requests/adapters.py", line 529, in send\n    raise ReadTimeout(e, request=request)\nrequests.exceptions.ReadTimeout: HTTPSConnectionPool(host='wcapi.covidclinic.org', port=443): Read timed out. (read timeout=5)
2022-08-22T14:14:28.027,ERROR,MainThread,140334522763072,cc_db.py:get_cc_order,290,No order document found for mrn=[00-905341]
2022-08-23T08:50:59.438,ERROR,MainThread,140594292852544,cc_db.py:get_order_json,237,HTTPSConnectionPool(host='wcapi.covidclinic.org' port=443): Read timed out. (read timeout=5)\nTraceback (most recent call last):\n  File "/usr/lib/python3/dist-packages/urllib3/contrib/pyopenssl.py", line 485, in wrap_socket\n    cnx.do_handshake()\n  File "/usr/lib/python3/dist-packages/OpenSSL/SSL.py", line 1915, in do_handshake\n    self._raise_ssl_error(self._ssl, result)\n  File "/usr/lib/python3/dist-packages/OpenSSL/SSL.py", line 1622, in _raise_ssl_error\n    raise WantReadError()\nOpenSSL.SSL.WantReadError\n\nDuring handling of the above exception, another exception occurred:\n\nTraceback (most recent call last):\n  File "/usr/lib/python3/dist-packages/urllib3/connectionpool.py", line 376, in _make_request\n    self._validate_conn(conn)\n  File "/usr/lib/python3/dist-packages/urllib3/connectionpool.py", line 996, in _validate_conn\n    conn.connect()\n  File "/usr/lib/python3/dist-packages/urllib3/connection.py", line 366, in connect\n    self.sock = ssl_wrap_socket(\n  File "/usr/lib/python3/dist-packages/urllib3/util/ssl_.py", line 370, in ssl_wrap_socket\n    return context.wrap_socket(sock, server_hostname=server_hostname)\n  File "/usr/lib/python3/dist-packages/urllib3/contrib/pyopenssl.py", line 488, in wrap_socket\n    raise timeout("select timed out")\nsocket.timeout: select timed out\n\nDuring handling of the above exception, another exception occurred:\n\nTraceback (most recent call last):\n  File "/usr/lib/python3/dist-packages/requests/adapters.py", line 439, in send\n    resp = conn.urlopen(\n  File "/usr/lib/python3/dist-packages/urllib3/connectionpool.py", line 719, in urlopen\n    retries = retries.increment(\n  File "/usr/lib/python3/dist-packages/urllib3/util/retry.py", line 400, in increment\n    raise six.reraise(type(error), error, _stacktrace)\n  File "/usr/lib/python3/dist-packages/six.py", line 703, in reraise\n    raise value\n  File "/usr/lib/python3/dist-packages/urllib3/connectionpool.py", line 665, in urlopen\n    httplib_response = self._make_request(\n  File "/usr/lib/python3/dist-packages/urllib3/connectionpool.py", line 379, in _make_request\n    self._raise_timeout(err=e, url=url, timeout_value=conn.timeout)\n  File "/usr/lib/python3/dist-packages/urllib3/connectionpool.py", line 330, in _raise_timeout\n    raise ReadTimeoutError(\nurllib3.exceptions.ReadTimeoutError: HTTPSConnectionPool(host='wcapi.covidclinic.org', port=443): Read timed out. (read timeout=5)\n\nDuring handling of the above exception, another exception occurred:\n\nTraceback (most recent call last):\n  File "/mnt/c/Users/malonso/Documents/auxiliary_api/Caladrius/cc_archive/cc_db.py", line 193, in get_order_json\n    order_response = wc_api[stage][site_code].get(f"orders/{order_number}")\n  File "/home/malonso/.local/lib/python3.8/site-packages/woocommerce/api.py", line 106, in get\n    return self.__request("GET", endpoint, None, **kwargs)\n  File "/home/malonso/.local/lib/python3.8/site-packages/woocommerce/api.py", line 92, in __request\n    return request(\n  File "/usr/lib/python3/dist-packages/requests/api.py", line 60, in request\n    return session.request(method=method, url=url, **kwargs)\n  File "/usr/lib/python3/dist-packages/requests/sessions.py", line 533, in request\n    resp = self.send(prep, **send_kwargs)\n  File "/usr/lib/python3/dist-packages/requests/sessions.py", line 646, in send\n    r = adapter.send(request, **kwargs)\n  File "/usr/lib/python3/dist-packages/requests/adapters.py", line 529, in send\n    raise ReadTimeout(e, request=request)\nrequests.exceptions.ReadTimeout: HTTPSConnectionPool(host='wcapi.covidclinic.org', port=443): Read timed out. (read timeout=5)
2022-08-23T08:50:59.488,ERROR,MainThread,140594292852544,cc_db.py:get_cc_order,290,No order document found for mrn=[00-958261]
2022-08-23T15:27:49.461,ERROR,MainThread,140511613814592,cc_db.py:get_order_json,237,HTTPSConnectionPool(host='wcapi.covidclinic.org' port=443): Read timed out. (read timeout=5)\nTraceback (most recent call last):\n  File "/usr/lib/python3/dist-packages/urllib3/contrib/pyopenssl.py", line 485, in wrap_socket\n    cnx.do_handshake()\n  File "/usr/lib/python3/dist-packages/OpenSSL/SSL.py", line 1915, in do_handshake\n    self._raise_ssl_error(self._ssl, result)\n  File "/usr/lib/python3/dist-packages/OpenSSL/SSL.py", line 1622, in _raise_ssl_error\n    raise WantReadError()\nOpenSSL.SSL.WantReadError\n\nDuring handling of the above exception, another exception occurred:\n\nTraceback (most recent call last):\n  File "/usr/lib/python3/dist-packages/urllib3/connectionpool.py", line 376, in _make_request\n    self._validate_conn(conn)\n  File "/usr/lib/python3/dist-packages/urllib3/connectionpool.py", line 996, in _validate_conn\n    conn.connect()\n  File "/usr/lib/python3/dist-packages/urllib3/connection.py", line 366, in connect\n    self.sock = ssl_wrap_socket(\n  File "/usr/lib/python3/dist-packages/urllib3/util/ssl_.py", line 370, in ssl_wrap_socket\n    return context.wrap_socket(sock, server_hostname=server_hostname)\n  File "/usr/lib/python3/dist-packages/urllib3/contrib/pyopenssl.py", line 488, in wrap_socket\n    raise timeout("select timed out")\nsocket.timeout: select timed out\n\nDuring handling of the above exception, another exception occurred:\n\nTraceback (most recent call last):\n  File "/usr/lib/python3/dist-packages/requests/adapters.py", line 439, in send\n    resp = conn.urlopen(\n  File "/usr/lib/python3/dist-packages/urllib3/connectionpool.py", line 719, in urlopen\n    retries = retries.increment(\n  File "/usr/lib/python3/dist-packages/urllib3/util/retry.py", line 400, in increment\n    raise six.reraise(type(error), error, _stacktrace)\n  File "/usr/lib/python3/dist-packages/six.py", line 703, in reraise\n    raise value\n  File "/usr/lib/python3/dist-packages/urllib3/connectionpool.py", line 665, in urlopen\n    httplib_response = self._make_request(\n  File "/usr/lib/python3/dist-packages/urllib3/connectionpool.py", line 379, in _make_request\n    self._raise_timeout(err=e, url=url, timeout_value=conn.timeout)\n  File "/usr/lib/python3/dist-packages/urllib3/connectionpool.py", line 330, in _raise_timeout\n    raise ReadTimeoutError(\nurllib3.exceptions.ReadTimeoutError: HTTPSConnectionPool(host='wcapi.covidclinic.org', port=443): Read timed out. (read timeout=5)\n\nDuring handling of the above exception, another exception occurred:\n\nTraceback (most recent call last):\n  File "/mnt/c/Users/malonso/Documents/auxiliary_api/Caladrius/cc_archive/cc_db.py", line 193, in get_order_json\n    order_response = wc_api[stage][site_code].get(f"orders/{order_number}")\n  File "/home/malonso/.local/lib/python3.8/site-packages/woocommerce/api.py", line 106, in get\n    return self.__request("GET", endpoint, None, **kwargs)\n  File "/home/malonso/.local/lib/python3.8/site-packages/woocommerce/api.py", line 92, in __request\n    return request(\n  File "/usr/lib/python3/dist-packages/requests/api.py", line 60, in request\n    return session.request(method=method, url=url, **kwargs)\n  File "/usr/lib/python3/dist-packages/requests/sessions.py", line 533, in request\n    resp = self.send(prep, **send_kwargs)\n  File "/usr/lib/python3/dist-packages/requests/sessions.py", line 646, in send\n    r = adapter.send(request, **kwargs)\n  File "/usr/lib/python3/dist-packages/requests/adapters.py", line 529, in send\n    raise ReadTimeout(e, request=request)\nrequests.exceptions.ReadTimeout: HTTPSConnectionPool(host='wcapi.covidclinic.org', port=443): Read timed out. (read timeout=5)
2022-08-23T15:27:49.548,ERROR,MainThread,140511613814592,cc_db.py:get_cc_order,290,No order document found for mrn=[00-746548]
2022-08-23T16:03:46.684,ERROR,MainThread,140133115561792,cc_db.py:get_order_json,237,HTTPSConnectionPool(host='wcapi.covidclinic.org' port=443): Read timed out. (read timeout=5)\nTraceback (most recent call last):\n  File "/usr/lib/python3/dist-packages/urllib3/contrib/pyopenssl.py", line 485, in wrap_socket\n    cnx.do_handshake()\n  File "/usr/lib/python3/dist-packages/OpenSSL/SSL.py", line 1915, in do_handshake\n    self._raise_ssl_error(self._ssl, result)\n  File "/usr/lib/python3/dist-packages/OpenSSL/SSL.py", line 1622, in _raise_ssl_error\n    raise WantReadError()\nOpenSSL.SSL.WantReadError\n\nDuring handling of the above exception, another exception occurred:\n\nTraceback (most recent call last):\n  File "/usr/lib/python3/dist-packages/urllib3/connectionpool.py", line 376, in _make_request\n    self._validate_conn(conn)\n  File "/usr/lib/python3/dist-packages/urllib3/connectionpool.py", line 996, in _validate_conn\n    conn.connect()\n  File "/usr/lib/python3/dist-packages/urllib3/connection.py", line 366, in connect\n    self.sock = ssl_wrap_socket(\n  File "/usr/lib/python3/dist-packages/urllib3/util/ssl_.py", line 370, in ssl_wrap_socket\n    return context.wrap_socket(sock, server_hostname=server_hostname)\n  File "/usr/lib/python3/dist-packages/urllib3/contrib/pyopenssl.py", line 488, in wrap_socket\n    raise timeout("select timed out")\nsocket.timeout: select timed out\n\nDuring handling of the above exception, another exception occurred:\n\nTraceback (most recent call last):\n  File "/usr/lib/python3/dist-packages/requests/adapters.py", line 439, in send\n    resp = conn.urlopen(\n  File "/usr/lib/python3/dist-packages/urllib3/connectionpool.py", line 719, in urlopen\n    retries = retries.increment(\n  File "/usr/lib/python3/dist-packages/urllib3/util/retry.py", line 400, in increment\n    raise six.reraise(type(error), error, _stacktrace)\n  File "/usr/lib/python3/dist-packages/six.py", line 703, in reraise\n    raise value\n  File "/usr/lib/python3/dist-packages/urllib3/connectionpool.py", line 665, in urlopen\n    httplib_response = self._make_request(\n  File "/usr/lib/python3/dist-packages/urllib3/connectionpool.py", line 379, in _make_request\n    self._raise_timeout(err=e, url=url, timeout_value=conn.timeout)\n  File "/usr/lib/python3/dist-packages/urllib3/connectionpool.py", line 330, in _raise_timeout\n    raise ReadTimeoutError(\nurllib3.exceptions.ReadTimeoutError: HTTPSConnectionPool(host='wcapi.covidclinic.org', port=443): Read timed out. (read timeout=5)\n\nDuring handling of the above exception, another exception occurred:\n\nTraceback (most recent call last):\n  File "/mnt/c/Users/malonso/Documents/auxiliary_api/Caladrius/cc_archive/cc_db.py", line 193, in get_order_json\n    order_response = wc_api[stage][site_code].get(f"orders/{order_number}")\n  File "/home/malonso/.local/lib/python3.8/site-packages/woocommerce/api.py", line 106, in get\n    return self.__request("GET", endpoint, None, **kwargs)\n  File "/home/malonso/.local/lib/python3.8/site-packages/woocommerce/api.py", line 92, in __request\n    return request(\n  File "/usr/lib/python3/dist-packages/requests/api.py", line 60, in request\n    return session.request(method=method, url=url, **kwargs)\n  File "/usr/lib/python3/dist-packages/requests/sessions.py", line 533, in request\n    resp = self.send(prep, **send_kwargs)\n  File "/usr/lib/python3/dist-packages/requests/sessions.py", line 646, in send\n    r = adapter.send(request, **kwargs)\n  File "/usr/lib/python3/dist-packages/requests/adapters.py", line 529, in send\n    raise ReadTimeout(e, request=request)\nrequests.exceptions.ReadTimeout: HTTPSConnectionPool(host='wcapi.covidclinic.org', port=443): Read timed out. (read timeout=5)
2022-08-23T16:03:46.702,ERROR,MainThread,140133115561792,cc_db.py:get_cc_order,290,No order document found for mrn=[00-905147]
2022-08-24T13:53:54.208,CRITICAL,MainThread,140221916448576,cc_db.py:get_cc_order,378,!!!! MRN mismatch! Order object MRN [2837658] != 00-2837658!
2022-08-24T13:53:59.337,CRITICAL,MainThread,140221916448576,cc_db.py:get_cc_order,378,!!!! MRN mismatch! Order object MRN [2837288] != 00-2837288!
2022-08-24T13:54:00.296,CRITICAL,MainThread,140221916448576,cc_db.py:get_cc_order,378,!!!! MRN mismatch! Order object MRN [2837594] != 00-2837594!
2022-08-24T13:54:03.067,CRITICAL,MainThread,140221916448576,cc_db.py:get_cc_order,378,!!!! MRN mismatch! Order object MRN [2837060] != 00-2837060!
2022-08-24T13:54:03.994,CRITICAL,MainThread,140221916448576,cc_db.py:get_cc_order,378,!!!! MRN mismatch! Order object MRN [2837487] != 00-2837487!
2022-08-24T13:55:38.838,CRITICAL,MainThread,140221916448576,cc_db.py:get_cc_order,378,!!!! MRN mismatch! Order object MRN [2839597] != 00-2839597!
2022-08-24T14:11:06.402,CRITICAL,MainThread,140221916448576,cc_db.py:get_cc_order,378,!!!! MRN mismatch! Order object MRN [2842419] != 00-2842419!
2022-08-24T14:11:08.021,CRITICAL,MainThread,140221916448576,cc_db.py:get_cc_order,378,!!!! MRN mismatch! Order object MRN [2843955] != 00-2843955!
2022-08-24T14:11:09.987,CRITICAL,MainThread,140221916448576,cc_db.py:get_cc_order,378,!!!! MRN mismatch! Order object MRN [2838145] != 00-2838145!
